<?xml version="1.0" encoding="utf-8"?>
<robot xmlns:xacro="http://wiki.ros.org/xacro">

  <xacro:include filename="inertial_macros.xacro"/>


  <link name="base_link"></link>

  <joint name="chassis_joint" type="fixed">
    <parent link="base_link" />
    <child link="still_chassis_assm" />
    <origin rpy="0.0 0 0" xyz="0 0 0" />
  </joint>

  <link name="still_chassis_assm">
    <visual>
      <origin xyz="0 0 0" rpy="0 -0 0" />
      <geometry>
        <mesh filename="package://catbot_description/meshes/visual/still_chassis_assm_visual.stl" />
      </geometry>
      <material name="still_chassis_assm_material">
        <color rgba="0.66987717125153911635 0.81712318213796708566 0.66602980483018847657 1.0" />
      </material>
    </visual>
    <collision>
      <origin xyz="0 0 0" rpy="0 -0 0" />
      <geometry>
        <mesh filename="package://catbot_description/meshes/collision/still_chassis_assm_collision.stl" />
      </geometry>
    </collision>
    <xacro:chassis_inertia/>
  </link>

  <link name="wheel_assm">
    <visual>
      <origin xyz="0 0 0" rpy="0 -0 0" />
      <geometry>
        <mesh filename="package://catbot_description/meshes/visual/wheel_assm_visual.stl" />
      </geometry>
      <material name="wheel_assm_material">
        <color rgba="0.34876043041436377568 0.28454440741211711741 0.12249285133838178075 1.0" />
      </material>
    </visual>
    <collision>
      <origin xyz="0 0 0" rpy="0 -0 0" />
      <geometry>
        <mesh filename="package://catbot_description/meshes/collision/wheel_assm_collision.stl" />
      </geometry>
    </collision>
    <xacro:wheel_inertia/> 
  </link>

  <joint name="rr_wheel" type="continuous">
    <origin xyz="-0.077614131532514007983 0.080478921592024327269 -0.030500000000000013212"
    rpy="-1.570796326794896558 0.67540343776289657463 -1.5707963267948956698" />
    <parent link="still_chassis_assm" />
    <child link="wheel_assm" />
    <axis xyz="0 0 1" />
    <limit effort="1" velocity="20" />
    <joint_properties friction="0.0" />
  </joint>

  <link name="wheel_assm_2">
    <visual>
      <origin xyz="0 0 0" rpy="0 -0 0" />
      <geometry>
        <mesh filename="package://catbot_description/meshes/visual/wheel_assm_2_visual.stl" />
      </geometry>
      <material name="wheel_assm_2_material">
        <color rgba="0.34876043041436377568 0.28454440741211711741 0.12249285133838178075 1.0" />
      </material>
    </visual>
    <collision>
      <origin xyz="0 0 0" rpy="0 -0 0" />
      <geometry>
        <mesh filename="package://catbot_description/meshes/collision/wheel_assm_2_collision.stl" />
      </geometry>
    </collision>
    <xacro:wheel_inertia/> 
  </link>

  <joint name="rf_wheel" type="continuous">
    <origin xyz="-0.077614131532534658131 -0.068021078407976207081 -0.030499999999999957701"
    rpy="1.570796326794896558 5.0445758681405589749e-15 1.570796326794896336" />
    <parent link="still_chassis_assm" />
    <child link="wheel_assm_2" />
    <axis xyz="0 0 1" />
    <limit effort="1" velocity="20" />
    <joint_properties friction="0.0" />
  </joint>

  <link name="wheel_assm_3">
    <visual>
      <origin xyz="0 0 0" rpy="0 -0 0" />
      <geometry>
        <mesh filename="package://catbot_description/meshes/visual/wheel_assm_3_visual.stl" />
      </geometry>
      <material name="wheel_assm_3_material">
        <color rgba="0.34876043041436383119 0.28454440741211711741 0.12249285133838178075 1.0" />
      </material>
    </visual>
    <collision>
      <origin xyz="0 0 0" rpy="0 -0 0" />
      <geometry>
        <mesh filename="package://catbot_description/meshes/collision/wheel_assm_3_collision.stl" />
      </geometry>
    </collision>
    <xacro:wheel_inertia/> 
  </link>

  <joint name="rl_wheel" type="continuous">
    <origin xyz="0.078385868467483257871 0.080478921592024507681 -0.030500000000000044437"
    rpy="-1.570796326794896558 -5.0445758681405660746e-15 1.5707963267948970021" />
    <parent link="still_chassis_assm" />
    <child link="wheel_assm_3" />
    <axis xyz="0 0 1" />
    <limit effort="1" velocity="20" />
    <joint_properties friction="0.0" />
  </joint>

  <link name="wheel_assm_4">
    <visual>
      <origin xyz="0 0 0" rpy="0 -0 0" />
      <geometry>
        <mesh filename="package://catbot_description/meshes/visual/wheel_assm_4_visual.stl" />
      </geometry>
      <material name="wheel_assm_4_material">
        <color rgba="0.34876043041436377568 0.28454440741211711741 0.12249285133838176687 1.0" />
      </material>
    </visual>
    <collision>
      <origin xyz="0 0 0" rpy="0 -0 0" />
      <geometry>
        <mesh filename="package://catbot_description/meshes/collision/wheel_assm_4_collision.stl" />
      </geometry>
    </collision>
    <xacro:wheel_inertia/> 
  </link>

  <joint name="fl_wheel" type="continuous">
    <origin xyz="0.078385868467507308077 -0.068021078407975985036 -0.030500000000000034028"
    rpy="-1.5707963267949118791 1.5703086100333234487 1.5707963267962468112" />
    <parent link="still_chassis_assm" />
    <child link="wheel_assm_4" />
    <axis xyz="0 0 1" />
    <limit effort="1" velocity="20" />
    <joint_properties friction="0.0" />
  </joint>
</robot>
